<?xml version="1.0" encoding="UTF-8"?>
<testng-results skipped="0" failed="2" total="2" passed="0">
  <reporter-output>
  </reporter-output>
  <suite name="Suite1" duration-ms="63" started-at="2016-06-01T05:40:36Z" finished-at="2016-06-01T05:40:36Z">
    <groups>
    </groups>
    <test name="test1" duration-ms="32" started-at="2016-06-01T05:40:36Z" finished-at="2016-06-01T05:40:36Z">
      <class name="com.cloudsmartz.test.TestCustomerAPI">
        <test-method status="FAIL" signature="delCustomer(java.lang.Integer)[pri:0, instance:com.cloudsmartz.test.TestCustomerAPI@29ee9faa]" name="delCustomer" duration-ms="16" started-at="2016-06-01T11:10:36Z" finished-at="2016-06-01T11:10:36Z">
          <params>
            <param index="0">
              <value>
                <![CDATA[-3]]>
              </value>
            </param>
          </params>
          <exception class="java.lang.AssertionError">
            <message>
              <![CDATA[expected [<406 Not Acceptable,{}>] but found [<201 Created,{}>]]]>
            </message>
            <full-stacktrace>
              <![CDATA[java.lang.AssertionError: expected [<406 Not Acceptable,{}>] but found [<201 Created,{}>]
	at org.testng.Assert.fail(Assert.java:94)
	at org.testng.Assert.failNotEquals(Assert.java:513)
	at org.testng.Assert.assertEqualsImpl(Assert.java:135)
	at org.testng.Assert.assertEquals(Assert.java:116)
	at org.testng.Assert.assertEquals(Assert.java:179)
	at com.cloudsmartz.test.TestCustomerAPI.delCustomer(TestCustomerAPI.java:53)
	at sun.reflect.NativeMethodAccessorImpl.invoke0(Native Method)
	at sun.reflect.NativeMethodAccessorImpl.invoke(NativeMethodAccessorImpl.java:62)
	at sun.reflect.DelegatingMethodAccessorImpl.invoke(DelegatingMethodAccessorImpl.java:43)
	at java.lang.reflect.Method.invoke(Method.java:497)
	at org.testng.internal.MethodInvocationHelper.invokeMethod(MethodInvocationHelper.java:86)
	at org.testng.internal.Invoker.invokeMethod(Invoker.java:643)
	at org.testng.internal.Invoker.invokeTestMethod(Invoker.java:820)
	at org.testng.internal.Invoker.invokeTestMethods(Invoker.java:1128)
	at org.testng.internal.TestMethodWorker.invokeTestMethods(TestMethodWorker.java:129)
	at org.testng.internal.TestMethodWorker.run(TestMethodWorker.java:112)
	at org.testng.TestRunner.privateRun(TestRunner.java:782)
	at org.testng.TestRunner.run(TestRunner.java:632)
	at org.testng.SuiteRunner.runTest(SuiteRunner.java:366)
	at org.testng.SuiteRunner.runSequentially(SuiteRunner.java:361)
	at org.testng.SuiteRunner.privateRun(SuiteRunner.java:319)
	at org.testng.SuiteRunner.run(SuiteRunner.java:268)
	at org.testng.SuiteRunnerWorker.runSuite(SuiteRunnerWorker.java:52)
	at org.testng.SuiteRunnerWorker.run(SuiteRunnerWorker.java:86)
	at org.testng.TestNG.runSuitesSequentially(TestNG.java:1244)
	at org.testng.TestNG.runSuitesLocally(TestNG.java:1169)
	at org.testng.TestNG.run(TestNG.java:1064)
	at org.testng.remote.AbstractRemoteTestNG.run(AbstractRemoteTestNG.java:126)
	at org.testng.remote.RemoteTestNG.initAndRun(RemoteTestNG.java:137)
	at org.testng.remote.RemoteTestNG.main(RemoteTestNG.java:58)
]]>
            </full-stacktrace>
          </exception> <!-- java.lang.AssertionError -->
          <reporter-output>
          </reporter-output>
        </test-method> <!-- delCustomer -->
        <test-method status="PASS" signature="init()[pri:0, instance:com.cloudsmartz.test.TestCustomerAPI@29ee9faa]" name="init" is-config="true" duration-ms="0" started-at="2016-06-01T11:10:36Z" finished-at="2016-06-01T11:10:36Z">
          <reporter-output>
          </reporter-output>
        </test-method> <!-- init -->
      </class> <!-- com.cloudsmartz.test.TestCustomerAPI -->
    </test> <!-- test1 -->
    <test name="test2" duration-ms="0" started-at="2016-06-01T05:40:36Z" finished-at="2016-06-01T05:40:36Z">
      <class name="com.cloudsmartz.test.TestCustomerAPI">
        <test-method status="FAIL" signature="delCustomer(java.lang.Integer)[pri:0, instance:com.cloudsmartz.test.TestCustomerAPI@ae45eb6]" name="delCustomer" duration-ms="0" started-at="2016-06-01T11:10:36Z" finished-at="2016-06-01T11:10:36Z">
          <params>
            <param index="0">
              <value>
                <![CDATA[-2]]>
              </value>
            </param>
          </params>
          <exception class="java.lang.AssertionError">
            <message>
              <![CDATA[expected [<406 Not Acceptable,{}>] but found [<201 Created,{}>]]]>
            </message>
            <full-stacktrace>
              <![CDATA[java.lang.AssertionError: expected [<406 Not Acceptable,{}>] but found [<201 Created,{}>]
	at org.testng.Assert.fail(Assert.java:94)
	at org.testng.Assert.failNotEquals(Assert.java:513)
	at org.testng.Assert.assertEqualsImpl(Assert.java:135)
	at org.testng.Assert.assertEquals(Assert.java:116)
	at org.testng.Assert.assertEquals(Assert.java:179)
	at com.cloudsmartz.test.TestCustomerAPI.delCustomer(TestCustomerAPI.java:53)
	at sun.reflect.NativeMethodAccessorImpl.invoke0(Native Method)
	at sun.reflect.NativeMethodAccessorImpl.invoke(NativeMethodAccessorImpl.java:62)
	at sun.reflect.DelegatingMethodAccessorImpl.invoke(DelegatingMethodAccessorImpl.java:43)
	at java.lang.reflect.Method.invoke(Method.java:497)
	at org.testng.internal.MethodInvocationHelper.invokeMethod(MethodInvocationHelper.java:86)
	at org.testng.internal.Invoker.invokeMethod(Invoker.java:643)
	at org.testng.internal.Invoker.invokeTestMethod(Invoker.java:820)
	at org.testng.internal.Invoker.invokeTestMethods(Invoker.java:1128)
	at org.testng.internal.TestMethodWorker.invokeTestMethods(TestMethodWorker.java:129)
	at org.testng.internal.TestMethodWorker.run(TestMethodWorker.java:112)
	at org.testng.TestRunner.privateRun(TestRunner.java:782)
	at org.testng.TestRunner.run(TestRunner.java:632)
	at org.testng.SuiteRunner.runTest(SuiteRunner.java:366)
	at org.testng.SuiteRunner.runSequentially(SuiteRunner.java:361)
	at org.testng.SuiteRunner.privateRun(SuiteRunner.java:319)
	at org.testng.SuiteRunner.run(SuiteRunner.java:268)
	at org.testng.SuiteRunnerWorker.runSuite(SuiteRunnerWorker.java:52)
	at org.testng.SuiteRunnerWorker.run(SuiteRunnerWorker.java:86)
	at org.testng.TestNG.runSuitesSequentially(TestNG.java:1244)
	at org.testng.TestNG.runSuitesLocally(TestNG.java:1169)
	at org.testng.TestNG.run(TestNG.java:1064)
	at org.testng.remote.AbstractRemoteTestNG.run(AbstractRemoteTestNG.java:126)
	at org.testng.remote.RemoteTestNG.initAndRun(RemoteTestNG.java:137)
	at org.testng.remote.RemoteTestNG.main(RemoteTestNG.java:58)
]]>
            </full-stacktrace>
          </exception> <!-- java.lang.AssertionError -->
          <reporter-output>
          </reporter-output>
        </test-method> <!-- delCustomer -->
        <test-method status="PASS" signature="init()[pri:0, instance:com.cloudsmartz.test.TestCustomerAPI@ae45eb6]" name="init" is-config="true" duration-ms="0" started-at="2016-06-01T11:10:36Z" finished-at="2016-06-01T11:10:36Z">
          <reporter-output>
          </reporter-output>
        </test-method> <!-- init -->
      </class> <!-- com.cloudsmartz.test.TestCustomerAPI -->
    </test> <!-- test2 -->
  </suite> <!-- Suite1 -->
</testng-results>
